Workbook

Sheet TrialBalance
A1: Client A
A2: Rodeo Imagination Inc. : Groupe Client A Inc (Consolidated)
A3: Trial Balance
A4: End of Dec 2024
B6: en CAD | C6: en EUR
A7: Account | B7: Total | C7: vlookup du B/S et P&L | D7: Taux
A8: 10000 - BANK
A9: 10625 - Compte courant LCL - Client A SAS (EUR | B9: 303244.71 | C9: =IFERROR(VLOOKUP(A9,BalanceSheet!$A:$B,2,0),0) -> 202569.63 | D9: =IFERROR(B9/C9,0) -> 1.49699
A10: 10630 - Compte courant BNP - Client A SAS (EUR) | B10: 827350.54 | C10: =IFERROR(VLOOKUP(A10,BalanceSheet!$A:$B,2,0),0) -> 552676.06 | D10: =IFERROR(B10/C10,0) -> 1.49699
A11: Total - 10000 - BANK | B11: =SUM(B9:B10) -> 1130595.2 | C11: =IFERROR(VLOOKUP(A11,BalanceSheet!$A:$B,2,0),0) -> 755245.69 | D11: =IFERROR(B11/C11,0) -> 1.49699
A12: 12000 - ACCOUNTS RECEIVABLE | C12: =IFERROR(VLOOKUP(A12,BalanceSheet!$A:$B,2,0),0) -> 0 | D12: =IFERROR(B12/C12,0) -> 0
A13: 12100 - Comptes clients | B13: 391196.45 | C13: =IFERROR(VLOOKUP(A13,BalanceSheet!$A:$B,2,0),0) -> 261322.02 | D13: =IFERROR(B13/C13,0) -> 1.49699
A14: 12200 - Comptes clients - intercos | B14: 269062.31 | C14: =IFERROR(VLOOKUP(A14,BalanceSheet!$A:$B,2,0),0) -> 179735.54 | D14: =IFERROR(B14/C14,0) -> 1.49699
A15: Total - 12000 - ACCOUNTS RECEIVABLE | B15: =SUM(B13:B14) -> 660258.76 | C15: =IFERROR(VLOOKUP(A15,BalanceSheet!$A:$B,2,0),0) -> 441057.56 | D15: =IFERROR(B15/C15,0) -> 1.49699
A16: 13000 - SALES TAXES ON PURCHASE | C16: =IFERROR(VLOOKUP(A16,BalanceSheet!$A:$B,2,0),0) -> 0 | D16: =IFERROR(B16/C16,0) -> 0
A17: 13356 - TVA déductible s/aut.biens et sces | B17: 6283.6604 | C17: =IFERROR(VLOOKUP(A17,BalanceSheet!$A:$B,2,0),0) -> 4197.53 | D17: =IFERROR(B17/C17,0) -> 1.49699
A18: 13358 - TVA déductible sur achats intracommunautaires | B18: 57.783814 | C18: =IFERROR(VLOOKUP(A18,BalanceSheet!$A:$B,2,0),0) -> 38.6 | D18: =IFERROR(B18/C18,0) -> 1.49699
A19: Total - 13000 - SALES TAXES ON PURCHASE | B19: =SUM(B17:B18) -> 6341.4442 | C19: =IFERROR(VLOOKUP(A19,BalanceSheet!$A:$B,2,0),0) -> 4236.13 | D19: =IFERROR(B19/C19,0) -> 1.49699
A20: 14000 - UNBILLED RECEIVABLE | C20: =IFERROR(VLOOKUP(A20,BalanceSheet!$A:$B,2,0),0) -> 0 | D20: =IFERROR(B20/C20,0) -> 0
A21: 14100 - Travaux en cours | B21: 803652.81 | C21: =IFERROR(VLOOKUP(A21,BalanceSheet!$A:$B,2,0),0) -> 536845.81 | D21: =IFERROR(B21/C21,0) -> 1.49699
A22: Total - 14000 - UNBILLED RECEIVABLE | B22: =SUM(B21) -> 803652.81 | C22: =IFERROR(VLOOKUP(A22,BalanceSheet!$A:$B,2,0),0) -> 536845.81 | D22: =IFERROR(B22/C22,0) -> 1.49699
A23: 15000 - PREPAID EXPENSES | C23: =IFERROR(VLOOKUP(A23,BalanceSheet!$A:$B,2,0),0) -> 0 | D23: =IFERROR(B23/C23,0) -> 0
A24: 15100 - Frais payés d'avance | B24: 231.28495 | C24: =IFERROR(VLOOKUP(A24,BalanceSheet!$A:$B,2,0),0) -> 154.5 | D24: =IFERROR(B24/C24,0) -> 1.49699
A25: Total - 15000 - PREPAID EXPENSES | B25: =SUM(B24) -> 231.28495 | C25: =IFERROR(VLOOKUP(A25,BalanceSheet!$A:$B,2,0),0) -> 154.5 | D25: =IFERROR(B25/C25,0) -> 1.49699
A26: 17000 - INVESTMENTS | C26: =IFERROR(VLOOKUP(A26,BalanceSheet!$A:$B,2,0),0) -> 0 | D26: =IFERROR(B26/C26,0) -> 0
A27: 17100 - Dépôts de garantie LT | B27: 610019.88 | C27: =IFERROR(VLOOKUP(A27,BalanceSheet!$A:$B,2,0),0) -> 407497.63 | D27: =IFERROR(B27/C27,0) -> 1.49699
A28: Total - 17000 - INVESTMENTS | B28: =SUM(B27) -> 610019.88 | C28: =IFERROR(VLOOKUP(A28,BalanceSheet!$A:$B,2,0),0) -> 407497.63 | D28: =IFERROR(B28/C28,0) -> 1.49699
A29: 18000 - FIXED ASSETS | C29: =IFERROR(VLOOKUP(A29,BalanceSheet!$A:$B,2,0),0) -> 0 | D29: =IFERROR(B29/C29,0) -> 0
A30: 18010 - Ameliorations locatives | B30: 46735.324 | C30: =IFERROR(VLOOKUP(A30,BalanceSheet!$A:$B,2,0),0) -> 31219.53 | D30: =IFERROR(B30/C30,0) -> 1.49699
A31: 18020 - Amort. cum. ameliorations locatives | B31: -4047.0526 | C31: =IFERROR(VLOOKUP(A31,BalanceSheet!$A:$B,2,0),0) -> -2703.46 | D31: =IFERROR(B31/C31,0) -> 1.49699
A32: 18110 - Équipements informatique | B32: 237033.07 | C32: =IFERROR(VLOOKUP(A32,BalanceSheet!$A:$B,2,0),0) -> 158339.78 | D32: =IFERROR(B32/C32,0) -> 1.49699
A33: 18120 - Amort cum. Équip. informatique | B33: -145853.38 | C33: =IFERROR(VLOOKUP(A33,BalanceSheet!$A:$B,2,0),0) -> -97431.1 | D33: =IFERROR(B33/C33,0) -> 1.49699
A34: 18310 - Équipement de photographie | B34: 9899.2356 | C34: =IFERROR(VLOOKUP(A34,BalanceSheet!$A:$B,2,0),0) -> 6612.76 | D34: =IFERROR(B34/C34,0) -> 1.49699
A35: 18320 - Amort. cum. Équip. photographie | B35: -1789.2773 | C35: =IFERROR(VLOOKUP(A35,BalanceSheet!$A:$B,2,0),0) -> -1195.25 | D35: =IFERROR(B35/C35,0) -> 1.49699
A36: 18350 - Équipement Audio | B36: 39019.104 | C36: =IFERROR(VLOOKUP(A36,BalanceSheet!$A:$B,2,0),0) -> 26065.04 | D36: =IFERROR(B36/C36,0) -> 1.49699
A37: 18360 - Amort.cum.équip. Audio | B37: -15220.466 | C37: =IFERROR(VLOOKUP(A37,BalanceSheet!$A:$B,2,0),0) -> -10167.38 | D37: =IFERROR(B37/C37,0) -> 1.49699
A38: 18410 - Mobilier de bureau & matériel | B38: 20427.551 | C38: =IFERROR(VLOOKUP(A38,BalanceSheet!$A:$B,2,0),0) -> 13645.75 | D38: =IFERROR(B38/C38,0) -> 1.49699
A39: 18420 - Amort. cum. - Matér./mobil./inst. | B39: -5772.8126 | C39: =IFERROR(VLOOKUP(A39,BalanceSheet!$A:$B,2,0),0) -> -3856.28 | D39: =IFERROR(B39/C39,0) -> 1.49699
A40: Total - 18000 - FIXED ASSETS | B40: =SUM(B30:B39) -> 180431.29 | C40: =IFERROR(VLOOKUP(A40,BalanceSheet!$A:$B,2,0),0) -> 120529.39 | D40: =IFERROR(B40/C40,0) -> 1.49699
A41: 21000 - ACCOUNTS PAYABLE | C41: =IFERROR(VLOOKUP(A41,BalanceSheet!$A:$B,2,0),0) -> 0 | D41: =IFERROR(B41/C41,0) -> 0
...

Sheet BalanceSheet
A1: Client A
A2: Rodeo Imagination Inc. : Groupe Client A Inc : Client A Inc. : Client A SAS
A3: Balance Sheet
A4: End of Dec 2024
A5: en Euro
A7: Financial Row | B7: Amount
A8: Current Assets
A9: Bank
A10: 10000 - BANK
A11: 10625 - Compte courant LCL - Client A SAS (EUR | B11: 202569.63
A12: 10630 - Compte courant BNP - Client A SAS (EUR) | B12: 552676.06
A13: Total - 10000 - BANK | B13: =SUM(B11:B12) -> 755245.69
A14: Total Bank | B14: =SUM(B13) -> 755245.69
A15: Accounts Receivable
A16: 12000 - ACCOUNTS RECEIVABLE
A17: 12100 - Comptes clients | B17: 261322.02
A18: 12200 - Comptes clients - intercos | B18: 179735.54
A19: Total - 12000 - ACCOUNTS RECEIVABLE | B19: =SUM(B17:B18) -> 441057.56
A20: Total Accounts Receivable | B20: =SUM(B19) -> 441057.56
A21: Unbilled Receivable
A22: 14000 - UNBILLED RECEIVABLE
A23: 14100 - Travaux en cours | B23: 536845.81
A24: Total - 14000 - UNBILLED RECEIVABLE | B24: =SUM(B23) -> 536845.81
A25: Total Unbilled Receivable | B25: =SUM(B24) -> 536845.81
A26: Other Current Asset
A27: 13000 - SALES TAXES ON PURCHASE
A28: 13356 - TVA déductible s/aut.biens et sces | B28: 4197.53
A29: 13358 - TVA déductible sur achats intracommunautaires | B29: 38.6
A30: Total - 13000 - SALES TAXES ON PURCHASE | B30: =SUM(B28:B29) -> 4236.13
A31: 15000 - PREPAID EXPENSES
A32: 15100 - Frais payés d'avance | B32: 154.5
A33: Total - 15000 - PREPAID EXPENSES | B33: =SUM(B32) -> 154.5
A34: Total Other Current Asset | B34: =SUM(B30,B33) -> 4390.63
A35: Total Current Assets | B35: =B14+B20+B25+B34 -> 1737539.7
A36: Fixed Assets
A37: 18000 - FIXED ASSETS
A38: 18010 - Ameliorations locatives | B38: 31219.53
A39: 18020 - Amort. cum. ameliorations locatives | B39: -2703.46
A40: 18110 - Équipements informatique | B40: 158339.78
A41: 18120 - Amort cum. Équip. informatique | B41: -97431.1
...

Sheet ProfitandLoss
A1: Client A
A2: Rodeo Imagination Inc. : Groupe Client A Inc : Client A Inc. : Client A SAS
A3: Profit and Loss
A4: From Jan 2024 to Dec 2024
A5: en Euro
A7: Financial Row | B7: Amount
A8: Sales
A9: 40000 - SALES
A10: 42000 - SALES REVENUE
A11: 42100 - Ventes | B11: 2381881.6
A12: 42110 - Prestations de services - Europe | B12: 16546.22
A13: 42200 - Revenus - intercos | B13: 1389978.1
A14: Total - 42000 - SALES REVENUE | B14: =SUM(B11:B13) -> 3788406
A15: 43000 - UNEARNED REVENUE
A16: 43100 - Variation TEC/RR | B16: 76598.05
A17: Total - 43000 - UNEARNED REVENUE | B17: =SUM(B16) -> 76598.05
A18: 44000 - OTHER REVENUE
A19: 44220 - Autres revenus | B19: 1027.57
A20: Total - 44000 - OTHER REVENUE | B20: =SUM(B19) -> 1027.57
A21: Total - 40000 - SALES | B21: =SUM(B14,B17,B20) -> 3866031.6
A22: Total - Sales | B22: =SUM(B21) -> 3866031.6
A23: Purchases
A24: 50000 - COST OF SALES
A25: 51000 - SALARIES AND SOCIAL CHARGES
A26: 51100 - Salaire COGS | B26: 1260791.9
A27: 51101 - Indemnités et avantages divers COGS (France) | B27: 10219.05
A28: 51206 - Cotisations à l'URSSAF COGS (France) | B28: 297486.35
A29: 51207 - Taxe d'apprentissage COGS (France) | B29: 7810.48
A30: 51208 - Formation continue (Organisme) COGS (France) | B30: 18900.92
A31: 51209 - Cotisations aux mutuelles COGS (France) | B31: 231.97
A32: 51210 - Cotisations aux caisses de retraite COGS (France) | B32: 127689.43
A33: 51211 - Cotisations Pôle Emploi COGS (France) | B33: 76525.94
A34: 51212 - Cotisations autres organismes COGS (France) | B34: 113965.69
A35: 51300 - Boni COGS | B35: 72000
A36: Total - 51000 - SALARIES AND SOCIAL CHARGES | B36: =SUM(B26:B35) -> 1985621.7
A37: 52000 - SUBCONTRACTORS
A38: 52100 - Sous-traitants compagnies | B38: 92408.68
A39: 52200 - Sous-traitants - intercos | B39: 390009.13
A40: 52400 - Sous-traitants artistes | B40: 31630
A41: Total - 52000 - SUBCONTRACTORS | B41: =SUM(B38:B40) -> 514047.81
...

Sheet Sheet2
